Workbook
Name AppliesTo_list: Settings!$A$2:$A$13
Name Evidence_list: Settings!$B$2:$B$11
Name FailureType_List: Settings!$D$2:$D$6
Name Severity_List: Settings!$C$2:$C$6

Sheet Engine_review_score
A1: INPUT | B1: Value
A2: ProductType(s) (use ; to separate)
A3: Productnaam
A4: Merk
A5: Batch/Lot
A6: THT/Productiedatum
A7: Review_datum | C7: Handmatig: vul de datum van de review in (YYYY-MM-DD). Backend: automatisch timestamp.
A8: Review_valid_until | B8: =IF(B7="","",DATE(YEAR(B7)+INT(B33/12),MONTH(B7)+MOD(B33,12),DAY(B7))) | C8: AUTO — berekend als Review_datum + Review_validity_months (MODEL SETTINGS B33). Backend: timestamp_review + validity_months.
A9: Review_trigger | C9: Handmatig: kies één trigger. Backend: automatisch bepaald door monitoring-service.
A10: Product_complexity_tier | B10: =IF(B26="","",IF(B26<=2,"Single",IF(B26<=6,"Multi","Complex"))) -> Single | C10: AUTO — berekend op basis van Ingredient_count (B26). Backend: count(product_ingredients WHERE product_id=current).
A11: Context_flags | B11: =B27 -> [BACKEND] Context flags worden automatisch berekend door de backend via de Context_Flag_Rules tabel. In productie: JOIN(matched_flags, " | ") op basis van product_ingredients + drempelwaarden. Zie sheet Context_Flag_Rules voor alle 59 regels. Handmatige override mogelijk via B11 (INPUT). | C11: AUTO — doorverwijzing naar Context_flags_computed (B27), samengesteld op basis van Context_Flag_Rules. Backend: JOIN(matched_flags, " | ").
A12: Reviewer | C12: Handmatig: naam of ID van de reviewer. Backend: user_id van ingelogde reviewer.
A14: HELPERS | B14: Value
A15: Has_Omega3 | B15: =IF(COUNTIF($B$2,"*OMEGA3*")>0,1,0) -> 0
A16: Has_Probiotic | B16: =IF(COUNTIF($B$2,"*PROBIOTIC*")>0,1,0) -> 0
A17: Has_Botanical | B17: =IF(ISNUMBER(LOOKUP("BOTANICAL",$B$2)),1,0) -> 0
A18: Has_Vitamin | B18: =IF(COUNTIF($B$2,"*VITAMIN*")>0,1,0) -> 0
A19: Has_Mineral | B19: =IF(COUNTIF($B$2,"*MINERAL*")>0,1,0) -> 0
A20: Has_Amino | B20: =IF(COUNTIF($B$2,"*AMINO*")>0,1,0) -> 0
A21: Has_Protein | B21: =IF(COUNTIF($B$2,"*PROTEIN*")>0,1,0) -> 0
A22: Has_Polyphenol | B22: =IF(COUNTIF($B$2,"*POLYPHENOL*")>0,1,0) -> 0
A23: Has_Enzyme | B23: =IF(COUNTIF($B$2,"*ENZYME*")>0,1,0) -> 0
A24: Has_Lipid | B24: =IF(COUNTIF($B$2,"*LIPID*")>0,1,0) -> 0
A25: Has_Sport | B25: =IF(COUNTIF($B$2,"*SPORT*")>0,1,0) -> 0
A26: Ingredient_count | B26: =COUNTA(ingredient_db) -> 1 | C26: AUTO — backend: COUNT(product_ingredients WHERE product_id = this product)
A27: Context_flags_computed | B27: ="[BACKEND] Context flags worden automatisch berekend door de backend via de Context_Flag_Rules tabel. "&"In productie: JOIN(matched_flags, "" | "") op basis van product_ingredients + drempelwaarden. "&"Zie sheet Context_Flag_Rules voor alle 59 regels. "&"Handmatige override mogelijk via B11 (INPUT)." -> [BACKEND] Context flags worden automatisch berekend door de backend via de Context_Flag_Rules tabel. In productie: JOIN(matched_flags, " | ") op basis van product_ingredients + drempelwaarden. Zie sheet Context_Flag_Rules voor alle 59 regels. Handmatige override mogelijk via B11 (INPUT). | C27: AUTO — samengesteld uit Context_Flag_Rules sheet (zie aparte tabel)
A29: MODEL SETTINGS | B29: Value
A30: CriticalFailCapPct | B30: 49
A31: CriteriaRowStart | B31: 37
A32: CriteriaRowEnd | B32: 1000
A33: Review_validity_months | B33: 12 | C33: Instelling — pas aan indien gewenst | Q33: Strong/Moderate/Weak | R33: b6_risk | pregnancy | sport_doping | ... | S33: Single | Multi | Complex | T33: YYYY-MM-DD | U33: annual | formula_change | new_safety_data | batch_change | recall_alert | V33: Auto (formula)
A34: Confidence_threshold_publish | B34: 0.6 | C34: Instelling — pas aan indien gewenst
A36: Category | B36: Criterion | C36: Weight | D36: Critical? (Y/N) | E36: AppliesTo | F36: Evidence to collect 1 | G36: Evidence to collect 2 | H36: Pass (1/0/-1) | I36: Applies (0/1) | J36: Score | K36: Notes | L36: QA_flag | M36: Severity | N36: Evidence_status | O36: Failure_type | P36: Consumer_impact | Q36: Evidence_quality | R36: Context_flags | S36: Product_complexity_tier | T36: Review_valid_until | U36: Review_trigger | V36: Confidence_score
A37: Identity & Labeling | B37: Alle actieve ingrediënten + exacte doseringen volledig gedeclareerd (geen proprietary blend). | C37: 8 | D37: Y | E37: ALL | F37: LABEL | I37: =IF($E37="ALL",1,IF(ISNUMBER(LOOKUP($E37,$B$2)),1,0)) -> 1 | J37: =IF(ISBLANK($H37),0,$C37*$H37*$I37) -> 0 | L37: =IF(AND($D37="Y",$H37=0,$I37=1),"CRITICAL FAIL",IF($H37=-1,"EVIDENCE MISSING","")) -> CRITICAL FAIL | M37: Critical Integrity | N37: Verified/Failed | O37: Compliance fail | P37: Consument kan dosering niet beoordelen of vergelijken.
A38: Identity & Labeling | B38: Alle chemische vormen expliciet gedeclareerd (geen “magnesium” zonder vorm). | C38: 8 | D38: Y | E38: ALL | F38: LABEL | I38: =IF($E38="ALL",1,IF(ISNUMBER(LOOKUP($E38,$B$2)),1,0)) -> 1 | J38: =IF(ISBLANK($H38),0,$C38*$H38*$I38) -> 0 | K38: v2: Weight 6→8: vorm bepaalt biobeschikbaarheid direct | L38: =IF(AND($D38="Y",$H38=0,$I38=1),"CRITICAL FAIL",IF($H38=-1,"EVIDENCE MISSING","")) -> CRITICAL FAIL | M38: Major | N38: Verified/Failed | O38: Compliance fail | P38: Biologische opname en effectiviteit onduidelijk.
A39: Identity & Labeling | B39: Alle hulpstoffen volledig gedeclareerd (capsulemateriaal, antiklontermiddelen, kleurstoffen, zoetstoffen). | C39: 5 | D39: Y | E39: ALL | F39: LABEL | I39: =IF($E39="ALL",1,IF(ISNUMBER(LOOKUP($E39,$B$2)),1,0)) -> 1 | J39: =IF(ISBLANK($H39),0,$C39*$H39*$I39) -> 0 | L39: =IF(AND($D39="Y",$H39=0,$I39=1),"CRITICAL FAIL",IF($H39=-1,"EVIDENCE MISSING","")) -> CRITICAL FAIL | M39: Major | N39: Verified/Failed | O39: Compliance fail | P39: Mogelijke allergenen of ongewenste additieven niet zichtbaar.
A40: Identity & Labeling | B40: Serving size, aanbevolen dagdosering en aantal servings per verpakking eenduidig vermeld. | C40: 5 | D40: Y | E40: ALL | F40: LABEL | I40: =IF($E40="ALL",1,IF(ISNUMBER(LOOKUP($E40,$B$2)),1,0)) -> 1 | J40: =IF(ISBLANK($H40),0,$C40*$H40*$I40) -> 0 | L40: =IF(AND($D40="Y",$H40=0,$I40=1),"CRITICAL FAIL",IF($H40=-1,"EVIDENCE MISSING","")) -> CRITICAL FAIL | M40: Major | N40: Verified/Failed | O40: Compliance fail | P40: Dagdosering en productduur niet betrouwbaar te bepalen.
A41: Identity & Labeling | B41: Batch/lot + THT/productiedatum duidelijk vermeld. | C41: 3 | D41: Y | E41: ALL | F41: LABEL | I41: =IF($E41="ALL",1,IF(ISNUMBER(LOOKUP($E41,$B$2)),1,0)) -> 1 | J41: =IF(ISBLANK($H41),0,$C41*$H41*$I41) -> 0 | L41: =IF(AND($D41="Y",$H41=0,$I41=1),"CRITICAL FAIL",IF($H41=-1,"EVIDENCE MISSING","")) -> CRITICAL FAIL | M41: Critical Integrity | N41: Verified/Failed | O41: Compliance fail | P41: Producttraceerbaarheid en recall onmogelijk.
A42: Identity & Labeling | B42: Contra-indicaties, allergenen en gebruiksaanwijzing helder gecommuniceerd. | C42: 4 | D42: Y | E42: ALL | F42: LABEL | G42: PACKAGING | I42: =IF($E42="ALL",1,IF(ISNUMBER(LOOKUP($E42,$B$2)),1,0)) -> 1 | J42: =IF(ISBLANK($H42),0,$C42*$H42*$I42) -> 0 | L42: =IF(AND($D42="Y",$H42=0,$I42=1),"CRITICAL FAIL",IF($H42=-1,"EVIDENCE MISSING","")) -> CRITICAL FAIL | M42: Critical Safety | N42: Verified/Failed | O42: Safety fail | P42: Verhoogd gezondheidsrisico bij verkeerd gebruik.
A43: Identity & Labeling | B43: Opslag- en stabiliteitsinstructies passend bij ingrediënttype vermeld. | C43: 3 | D43: N | E43: ALL | F43: LABEL | G43: PACKAGING | I43: =IF($E43="ALL",1,IF(ISNUMBER(LOOKUP($E43,$B$2)),1,0)) -> 1 | J43: =IF(ISBLANK($H43),0,$C43*$H43*$I43) -> 0 | L43: =IF(AND($D43="Y",$H43=0,$I43=1),"CRITICAL FAIL",IF($H43=-1,"EVIDENCE MISSING","")) | M43: Minor | N43: Verified/Failed | O43: Compliance fail | P43: Potentie kan sneller afnemen bij verkeerde opslag.
...

Sheet Category_modules
A1: Producttype | B1: =Engine_review_score!B2 -> 0
A4: ModuleType | B4: AppliesTo | C4: Criterion | D4: Weight | E4: Critical | F4: Evidence | G4: Pass | H4: Applies | I4: Score | J4: Notes | K4: QA_flag | L4: Severity | M4: Evidence_status | N4: Failure_type | O4: Consumer_impact | P4: Evidence_quality | Q4: Context_flags | R4: Review_valid_until | S4: Review_trigger
A5: Omega3 | B5: OMEGA3 | C5: EPA + DHA exact per dosering + totale omega-3 duidelijk vermeld (geen generieke “fish oil” without specification). | D5: 8 | E5: Y | F5: label | H5: =IF($B5=$B$1,1,0) -> 0 | I5: =IF(ISBLANK($G5),0,$D5*$G5*$H5) -> 0 | K5: =IF(AND($E5="Y",$G5=0,$H5=1),"CRITICAL FAIL",IF($G5=-1,"EVIDENCE MISSING","")) | L5: Critical Integrity | M5: Verified/Failed | N5: Compliance fail | O5: Consument kan werkelijke EPA/DHA-dosering niet beoordelen; effectiviteit en vergelijkbaarheid tussen producten onduidelijk.
A6: Omega3 | B6: OMEGA3 | C6: Vorm gespecificeerd (TG/rTG/PL/EE) en plausibel voor producttype. | D6: 6 | E6: N | F6: label/spec | H6: =IF($B6=$B$1,1,0) -> 0 | I6: =IF(ISBLANK($G6),0,$D6*$G6*$H6) -> 0 | K6: =IF(AND($E6="Y",$G6=0,$H6=1),"CRITICAL FAIL",IF($G6=-1,"EVIDENCE MISSING","")) | L6: Major | M6: Verified/Failed | N6: Quality fail | O6: Onbekende vetzuurvorm kan lagere biologische beschikbaarheid of minder geschikte opname geven.
A7: Omega3 | B7: OMEGA3 | C7: Oxidatiecontrole volledig en batch-specifiek onder acceptabele limieten (PV ≤5, AV ≤20, TOTOX ≤26). | D7: 9 | E7: Y | F7: COA | H7: =IF($B7=$B$1,1,0) -> 0 | I7: =IF(ISBLANK($G7),0,$D7*$G7*$H7) -> 0 | K7: =IF(AND($E7="Y",$G7=0,$H7=1),"CRITICAL FAIL",IF($G7=-1,"EVIDENCE MISSING","")) | L7: Critical Safety | M7: Verified/Missing | N7: Safety fail | O7: Risico op geoxideerde olie; mogelijke blootstelling aan schadelijke oxidatieproducten.
A8: Omega3 | B8: OMEGA3 | C8: Dioxines en PCB’s batch-specifiek getest en binnen veilige limieten. | D8: 10 | E8: Y | F8: COA | H8: =IF($B8=$B$1,1,0) -> 0 | I8: =IF(ISBLANK($G8),0,$D8*$G8*$H8) -> 0 | K8: =IF(AND($E8="Y",$G8=0,$H8=1),"CRITICAL FAIL",IF($G8=-1,"EVIDENCE MISSING","")) | L8: Critical Safety | M8: Verified/Missing | N8: Safety fail | O8: Mogelijke blootstelling aan persistente toxische stoffen (dioxines/PCB’s) met lange-termijn gezondheidsrisico.
A9: Omega3 | B9: OMEGA3 | C9: Zware metalen aantoonbaar ruim onder EU-limieten voor mariene oliën. | D9: 10 | E9: Y | F9: COA | H9: =IF($B9=$B$1,1,0) -> 0 | I9: =IF(ISBLANK($G9),0,$D9*$G9*$H9) -> 0 | K9: =IF(AND($E9="Y",$G9=0,$H9=1),"CRITICAL FAIL",IF($G9=-1,"EVIDENCE MISSING","")) | L9: Critical Safety | M9: Verified/Missing | N9: Safety fail | O9: Mogelijke blootstelling aan zware metalen uit mariene bronnen.
A10: Omega3 | B10: OMEGA3 | C10: Antioxidantbescherming aanwezig (bijv. tocoferolen) en verpakking geschikt tegen oxidatie (donkere fles/softgelmatrix). | D10: 5 | E10: N | F10: label/spec | H10: =IF($B10=$B$1,1,0) -> 0 | I10: =IF(ISBLANK($G10),0,$D10*$G10*$H10) -> 0 | K10: =IF(AND($E10="Y",$G10=0,$H10=1),"CRITICAL FAIL",IF($G10=-1,"EVIDENCE MISSING","")) | L10: Major | M10: Verified/Failed | N10: Quality fail | O10: Versnelde oxidatie kan productkwaliteit en werkzaamheid verminderen.
A11: Omega3 | B11: OMEGA3 | C11: Effectieve EPA+DHA hoeveelheid per dagdosering klinisch relevant (≥500–1000 mg afhankelijk van positionering). | D11: 7 | E11: N | F11: label/literature | H11: =IF($B11=$B$1,1,0) -> 0 | I11: =IF(ISBLANK($G11),0,$D11*$G11*$H11) -> 0 | K11: =IF(AND($E11="Y",$G11=0,$H11=1),"CRITICAL FAIL",IF($G11=-1,"EVIDENCE MISSING","")) | L11: Major | M11: Verified/Failed | N11: Quality fail | O11: Dosering mogelijk te laag voor klinisch relevant effect; consument verwacht mogelijk werking die niet optreedt.
A12: Omega3 | B12: OMEGA3 | C12: Brontransparantie aanwezig (vissoort of algensoort vermeld). | D12: 4 | E12: N | F12: label/spec | H12: =IF($B12=$B$1,1,0) -> 0 | I12: =IF(ISBLANK($G12),0,$D12*$G12*$H12) -> 0 | K12: =IF(AND($E12="Y",$G12=0,$H12=1),"CRITICAL FAIL",IF($G12=-1,"EVIDENCE MISSING","")) | L12: Minor | M12: Verified/Failed | N12: Quality fail | O12: Onbekende bron belemmert beoordeling van duurzaamheid, allergenen of oxidatierisico.
A13: Omega3 | B13: OMEGA3 | C13: Onafhankelijke kwaliteitscertificering aanwezig indien geclaimd (bijv. IFOS of vergelijkbaar). | D13: 4 | E13: N | F13: certification | H13: =IF($B13=$B$1,1,0) -> 0 | I13: =IF(ISBLANK($G13),0,$D13*$G13*$H13) -> 0 | K13: =IF(AND($E13="Y",$G13=0,$H13=1),"CRITICAL FAIL",IF($G13=-1,"EVIDENCE MISSING","")) | L13: Minor | M13: Verified/Missing | N13: Claim fail | O13: Kwaliteitsclaim niet controleerbaar; consument kan betrouwbaarheid van product moeilijk beoordelen.
A14: Omega3 | B14: OMEGA3 | C14: Dopingcertificering aanwezig indien product sportgericht gepositioneerd wordt. | D14: 7 | E14: Y | F14: certification | H14: =IF($B14=$B$1,1,0) -> 0 | I14: =IF(ISBLANK($G14),0,$D14*$G14*$H14) -> 0 | K14: =IF(AND($E14="Y",$G14=0,$H14=1),"CRITICAL FAIL",IF($G14=-1,"EVIDENCE MISSING","")) | L14: Critical Integrity | M14: Verified/Missing | N14: Safety fail | O14: Mogelijk risico voor sporters als product niet aantoonbaar vrij is van dopingrelevante contaminanten.
K15: =IF(AND($E15="Y",$G15=0,$H15=1),"CRITICAL FAIL",IF($G15=-1,"EVIDENCE MISSING",""))
A16: Probiotic | B16: PROBIOTIC | C16: Genus + species + straincode volledig vermeld (bijv. ATCC/DSM/BB-12 etc.). | D16: 8 | E16: Y | F16: label | H16: =IF($B16=$B$1,1,0) -> 0 | I16: =IF(ISBLANK($G16),0,$D16*$G16*$H16) -> 0 | K16: =IF(AND($E16="Y",$G16=0,$H16=1),"CRITICAL FAIL",IF($G16=-1,"EVIDENCE MISSING","")) | L16: Critical Integrity | M16: Verified/Failed | N16: Compliance fail | O16: Zonder volledige strain-identificatie is de werking niet herleidbaar naar klinisch onderzochte probiotische stammen.
A17: Probiotic | B17: PROBIOTIC | C17: CFU per strain gespecificeerd (niet alleen totaal CFU in blend). | D17: 6 | E17: Y | F17: label/spec | H17: =IF($B17=$B$1,1,0) -> 0 | I17: =IF(ISBLANK($G17),0,$D17*$G17*$H17) -> 0 | K17: =IF(AND($E17="Y",$G17=0,$H17=1),"CRITICAL FAIL",IF($G17=-1,"EVIDENCE MISSING","")) | L17: Major | M17: Verified/Failed | N17: Quality fail | O17: Onbekend hoeveel CFU per stam aanwezig is; effectiviteit van de formule niet betrouwbaar te beoordelen.
A18: Probiotic | B18: PROBIOTIC | C18: CFU gegarandeerd tot einde THT (niet alleen “at manufacture”). | D18: 8 | E18: Y | F18: spec/stability | H18: =IF($B18=$B$1,1,0) -> 0 | I18: =IF(ISBLANK($G18),0,$D18*$G18*$H18) -> 0 | K18: =IF(AND($E18="Y",$G18=0,$H18=1),"CRITICAL FAIL",IF($G18=-1,"EVIDENCE MISSING","")) | L18: Critical Safety | M18: Verified/Missing | N18: Quality fail | O18: CFU kan sterk dalen vóór einde THT; consument krijgt mogelijk minder levende bacteriën dan verwacht.
A19: Probiotic | B19: PROBIOTIC | C19: Strain-identiteit analytisch bevestigd (bijv. whole genome sequencing of gevalideerde methode). | D19: 9 | E19: Y | F19: spec/COA | H19: =IF($B19=$B$1,1,0) -> 0 | I19: =IF(ISBLANK($G19),0,$D19*$G19*$H19) -> 0 | K19: =IF(AND($E19="Y",$G19=0,$H19=1),"CRITICAL FAIL",IF($G19=-1,"EVIDENCE MISSING","")) | L19: Critical Integrity | M19: Verified/Missing | N19: Quality fail | O19: Onbekende strain-identiteit kan leiden tot onbetrouwbare werking of verkeerde bacteriestam.
A20: Probiotic | B20: PROBIOTIC | C20: Afwezigheid overdraagbare antibiotic resistance genes aantoonbaar gecontroleerd. | D20: 9 | E20: Y | F20: spec/COA | H20: =IF($B20=$B$1,1,0) -> 0 | I20: =IF(ISBLANK($G20),0,$D20*$G20*$H20) -> 0 | K20: =IF(AND($E20="Y",$G20=0,$H20=1),"CRITICAL FAIL",IF($G20=-1,"EVIDENCE MISSING","")) | L20: Critical Safety | M20: Verified/Missing | N20: Safety fail | O20: Mogelijk risico op overdraagbare antibiotic resistance genes in bacteriestammen.
A21: Probiotic | B21: PROBIOTIC | C21: Opslag- en vochtbescherming passend voor levensvatbaarheid (blister/barrière verpakking/desiccant waar nodig). | D21: 6 | E21: N | F21: spec/packaging | H21: =IF($B21=$B$1,1,0) -> 0 | I21: =IF(ISBLANK($G21),0,$D21*$G21*$H21) -> 0 | K21: =IF(AND($E21="Y",$G21=0,$H21=1),"CRITICAL FAIL",IF($G21=-1,"EVIDENCE MISSING","")) | L21: Major | M21: Verified/Failed | N21: Quality fail | O21: Onvoldoende bescherming tegen vocht of zuurstof kan snelle afname van levensvatbare bacteriën veroorzaken.
A22: Probiotic | B22: PROBIOTIC | C22: Stabiliteit aangetoond onder realistische opslagcondities (niet alleen ideale labcondities). | D22: 7 | E22: Y | F22: stability data | H22: =IF($B22=$B$1,1,0) -> 0 | I22: =IF(ISBLANK($G22),0,$D22*$G22*$H22) -> 0 | K22: =IF(AND($E22="Y",$G22=0,$H22=1),"CRITICAL FAIL",IF($G22=-1,"EVIDENCE MISSING","")) | L22: Critical Safety | M22: Verified/Missing | N22: Quality fail | O22: Levensvatbaarheid van bacteriën mogelijk overschat wanneer stabiliteit alleen onder ideale omstandigheden getest is.
A23: Probiotic | B23: PROBIOTIC | C23: Strain-specifieke klinische onderbouwing aanwezig voor geclaimde werking. | D23: 6 | E23: N | F23: literature | H23: =IF($B23=$B$1,1,0) -> 0 | I23: =IF(ISBLANK($G23),0,$D23*$G23*$H23) -> 0 | K23: =IF(AND($E23="Y",$G23=0,$H23=1),"CRITICAL FAIL",IF($G23=-1,"EVIDENCE MISSING","")) | L23: Major | M23: Verified/Failed | N23: Claim fail | O23: Geclaimde gezondheidswerking mogelijk niet onderbouwd met klinisch bewijs voor de gebruikte stam.
A24: Probiotic | B24: PROBIOTIC | C24: Formulering ondersteunt overleving door maagzuur waar relevant (matrix/enteric bescherming). | D24: 5 | E24: N | F24: spec/formulation | H24: =IF($B24=$B$1,1,0) -> 0 | I24: =IF(ISBLANK($G24),0,$D24*$G24*$H24) -> 0 | K24: =IF(AND($E24="Y",$G24=0,$H24=1),"CRITICAL FAIL",IF($G24=-1,"EVIDENCE MISSING","")) | L24: Major | M24: Verified/Failed | N24: Quality fail | O24: Onvoldoende bescherming tegen maagzuur kan leiden tot lage overleving van bacteriën en verminderde effectiviteit.
K25: =IF(AND($E25="Y",$G25=0,$H25=1),"CRITICAL FAIL",IF($G25=-1,"EVIDENCE MISSING",""))
A26: Botanical | B26: BOTANICAL | C26: Latijnse plantnaam (genus + species), plantdeel en herkomst duidelijk gespecificeerd. | D26: 8 | E26: Y | F26: label/spec | H26: =IF($B26=$B$1,1,0) -> 0 | I26: =IF(ISBLANK($G26),0,$D26*$G26*$H26) -> 0 | K26: =IF(AND($E26="Y",$G26=0,$H26=1),"CRITICAL FAIL",IF($G26=-1,"EVIDENCE MISSING","")) | L26: Critical Integrity | M26: Verified/Failed | N26: Compliance fail | O26: Onvoldoende specificatie van plantsoort of plantdeel maakt identificatie en vergelijking van het ingrediënt onmogelijk.
A27: Botanical | B27: BOTANICAL | C27: Extractratio en extracttype transparant en plausibel vermeld. | D27: 6 | E27: N | F27: label/spec | H27: =IF($B27=$B$1,1,0) -> 0 | I27: =IF(ISBLANK($G27),0,$D27*$G27*$H27) -> 0 | K27: =IF(AND($E27="Y",$G27=0,$H27=1),"CRITICAL FAIL",IF($G27=-1,"EVIDENCE MISSING","")) | L27: Major | M27: Verified/Failed | N27: Quality fail | O27: Onbekende extractiemethode of ratio maakt potentie en concentratie van actieve stoffen onduidelijk.
A28: Botanical | B28: BOTANICAL | C28: Standaardisatie op markercompound of actieve fractie (%) duidelijk vermeld. | D28: 7 | E28: Y | F28: label/spec/COA | H28: =IF($B28=$B$1,1,0) -> 0 | I28: =IF(ISBLANK($G28),0,$D28*$G28*$H28) -> 0 | K28: =IF(AND($E28="Y",$G28=0,$H28=1),"CRITICAL FAIL",IF($G28=-1,"EVIDENCE MISSING","")) | L28: Critical Integrity | M28: Verified/Missing | N28: Quality fail | O28: Zonder duidelijke standaardisatie is de hoeveelheid actieve stoffen onvoorspelbaar.
A29: Botanical | B29: BOTANICAL | C29: Markercompound klinisch relevant voor de geclaimde werking. | D29: 6 | E29: N | F29: literature/spec | H29: =IF($B29=$B$1,1,0) -> 0 | I29: =IF(ISBLANK($G29),0,$D29*$G29*$H29) -> 0 | K29: =IF(AND($E29="Y",$G29=0,$H29=1),"CRITICAL FAIL",IF($G29=-1,"EVIDENCE MISSING","")) | L29: Major | M29: Verified/Failed | N29: Claim fail | O29: Geclaimde werking kan niet logisch worden gekoppeld aan een relevante actieve markerstof.
A30: Botanical | B30: BOTANICAL | C30: Botanische identiteit analytisch bevestigd (bijv. HPLC/HPTLC fingerprint of DNA-analyse). | D30: 9 | E30: Y | F30: spec/COA | H30: =IF($B30=$B$1,1,0) -> 0 | I30: =IF(ISBLANK($G30),0,$D30*$G30*$H30) -> 0 | K30: =IF(AND($E30="Y",$G30=0,$H30=1),"CRITICAL FAIL",IF($G30=-1,"EVIDENCE MISSING","")) | L30: Critical Integrity | M30: Verified/Missing | N30: Quality fail | O30: Identiteit van de botanische grondstof niet analytisch bevestigd; risico op verkeerde plantsoort.
A31: Botanical | B31: BOTANICAL | C31: Adulteratie of botanische substitutie aantoonbaar uitgesloten. | D31: 9 | E31: Y | F31: spec/COA | H31: =IF($B31=$B$1,1,0) -> 0 | I31: =IF(ISBLANK($G31),0,$D31*$G31*$H31) -> 0 | K31: =IF(AND($E31="Y",$G31=0,$H31=1),"CRITICAL FAIL",IF($G31=-1,"EVIDENCE MISSING","")) | L31: Critical Integrity | M31: Verified/Missing | N31: Safety fail | O31: Risico op vervalsing of substitutie met andere plantsoorten met mogelijk andere veiligheid of werking.
A32: Botanical | B32: BOTANICAL | C32: Pesticiden en herbiciden getest en binnen veilige limieten. | D32: 8 | E32: Y | F32: COA | H32: =IF($B32=$B$1,1,0) -> 0 | I32: =IF(ISBLANK($G32),0,$D32*$G32*$H32) -> 0 | K32: =IF(AND($E32="Y",$G32=0,$H32=1),"CRITICAL FAIL",IF($G32=-1,"EVIDENCE MISSING","")) | L32: Critical Safety | M32: Verified/Missing | N32: Safety fail | O32: Mogelijke blootstelling aan pesticiden of herbiciden uit teelt van botanische grondstoffen.
A33: Botanical | B33: BOTANICAL | C33: Mycotoxinen getest waar relevant voor botanische grondstoffen. | D33: 7 | E33: Y | F33: COA | H33: =IF($B33=$B$1,1,0) -> 0 | I33: =IF(ISBLANK($G33),0,$D33*$G33*$H33) -> 0 | K33: =IF(AND($E33="Y",$G33=0,$H33=1),"CRITICAL FAIL",IF($G33=-1,"EVIDENCE MISSING","")) | L33: Critical Safety | M33: Verified/Missing | N33: Safety fail | O33: Risico op blootstelling aan mycotoxinen uit schimmelgroei tijdens teelt of opslag.
A34: Botanical | B34: BOTANICAL | C34: Oplosmiddelresiduen binnen ICH Q3C limieten. | D34: 8 | E34: Y | F34: COA | H34: =IF($B34=$B$1,1,0) -> 0 | I34: =IF(ISBLANK($G34),0,$D34*$G34*$H34) -> 0 | K34: =IF(AND($E34="Y",$G34=0,$H34=1),"CRITICAL FAIL",IF($G34=-1,"EVIDENCE MISSING","")) | L34: Critical Safety | M34: Verified/Missing | N34: Safety fail | O34: Mogelijke aanwezigheid van residuele oplosmiddelen uit extractieproces.
A35: Botanical | B35: BOTANICAL | C35: Batch-to-batch consistentie van markercompound of actieve fractie aantoonbaar. | D35: 6 | E35: N | F35: spec/COA | H35: =IF($B35=$B$1,1,0) -> 0 | I35: =IF(ISBLANK($G35),0,$D35*$G35*$H35) -> 0 | K35: =IF(AND($E35="Y",$G35=0,$H35=1),"CRITICAL FAIL",IF($G35=-1,"EVIDENCE MISSING","")) | L35: Major | M35: Verified/Missing | N35: Quality fail | O35: Variatie tussen batches kan leiden tot onvoorspelbare werking of inconsistent producteffect.
K36: =IF(AND($E36="Y",$G36=0,$H36=1),"CRITICAL FAIL",IF($G36=-1,"EVIDENCE MISSING",""))
A37: Vitamin | B37: VITAMIN | C37: Vitaminevorm expliciet gedeclareerd voor alle vitaminen (geen generieke “vitamin B complex” zonder vormen). | D37: 7 | E37: Y | F37: label | H37: =IF($B37=$B$1,1,0) -> 0 | I37: =IF(ISBLANK($G37),0,$D37*$G37*$H37) -> 0 | K37: =IF(AND($E37="Y",$G37=0,$H37=1),"CRITICAL FAIL",IF($G37=-1,"EVIDENCE MISSING","")) | L37: Critical Integrity | M37: Verified/Failed | N37: Compliance fail | O37: Consument kan niet zien welke specifieke vitaminevormen aanwezig zijn; effectiviteit en vergelijkbaarheid met andere producten onduidelijk.
A38: Vitamin | B38: VITAMIN | C38: Vitamine D vorm = cholecalciferol (D3) tenzij duidelijke rationale voor D2. | D38: 6 | E38: N | F38: label | H38: =IF($B38=$B$1,1,0) -> 0 | I38: =IF(ISBLANK($G38),0,$D38*$G38*$H38) -> 0 | K38: =IF(AND($E38="Y",$G38=0,$H38=1),"CRITICAL FAIL",IF($G38=-1,"EVIDENCE MISSING","")) | L38: Major | M38: Verified/Failed | N38: Quality fail | O38: Minder effectieve vitamine D-vorm kan worden gebruikt waardoor biologische beschikbaarheid lager is.
A39: Vitamin | B39: VITAMIN | C39: Vitamine K2 vorm gespecificeerd (MK-7 all-trans of equivalent bewijs). | D39: 6 | E39: N | F39: label/spec | H39: =IF($B39=$B$1,1,0) -> 0 | I39: =IF(ISBLANK($G39),0,$D39*$G39*$H39) -> 0 | K39: =IF(AND($E39="Y",$G39=0,$H39=1),"CRITICAL FAIL",IF($G39=-1,"EVIDENCE MISSING","")) | L39: Major | M39: Verified/Failed | N39: Quality fail | O39: Onbekende K2-vorm maakt effectiviteit en stabiliteit van het ingrediënt onzeker.
A40: Vitamin | B40: VITAMIN | C40: Folaatvorm biologisch actief (5-MTHF) waar relevant i.p.v. uitsluitend foliumzuur. | D40: 6 | E40: N | F40: label | H40: =IF($B40=$B$1,1,0) -> 0 | I40: =IF(ISBLANK($G40),0,$D40*$G40*$H40) -> 0 | K40: =IF(AND($E40="Y",$G40=0,$H40=1),"CRITICAL FAIL",IF($G40=-1,"EVIDENCE MISSING","")) | L40: Major | M40: Verified/Failed | N40: Quality fail | O40: Foliumzuur kan minder efficiënt worden omgezet bij sommige gebruikers; biologische benutting kan beperkt zijn.
A41: Vitamin | B41: VITAMIN | C41: Vitamine B12 vorm biologisch actief (methyl/hydroxy/adenosyl) i.p.v. cyanocobalamine als hoofdvorm. | D41: 6 | E41: N | F41: label | H41: =IF($B41=$B$1,1,0) -> 0 | I41: =IF(ISBLANK($G41),0,$D41*$G41*$H41) -> 0 | K41: =IF(AND($E41="Y",$G41=0,$H41=1),"CRITICAL FAIL",IF($G41=-1,"EVIDENCE MISSING","")) | L41: Major | M41: Verified/Failed | N41: Quality fail | O41: Minder biologisch actieve B12-vorm kan leiden tot lagere opname en effectiviteit.
A42: Vitamin | B42: VITAMIN | C42: Vitamine B6 dosering veilig voor langdurig gebruik (geen structurele dosering >25 mg zonder duidelijke context). | D42: 8 | E42: Y | F42: label/literature | H42: =IF($B42=$B$1,1,0) -> 0 | I42: =IF(ISBLANK($G42),0,$D42*$G42*$H42) -> 0 | K42: =IF(AND($E42="Y",$G42=0,$H42=1),"CRITICAL FAIL",IF($G42=-1,"EVIDENCE MISSING","")) | L42: Critical Safety | M42: Verified/Failed | N42: Safety fail | O42: Te hoge B6-dosering kan bij langdurig gebruik neurologische klachten veroorzaken.
...

Sheet Context_Flag_Rules
A1: FUNCIFY — Context Flag Rules
A2: Elke regel definieert één logische conditie die automatisch een context_flag triggert op een product. De backend (Python/Node.js) loopt bij iedere product-review door deze tabel en evalueert alle actieve regels. Vlag wordt gezet wanneer aan de conditie voldaan is. Meerdere vlaggen worden samengevoegd als " | "-string.
A3: Developer note: deze tabel is de machine-readable mapping. In Airtable: tabel "CONTEXT_FLAG_RULES" met velden rule_id, ingredient_name, operator, threshold_value, threshold_unit, flag, flag_category, severity, intake_match_field, consumer_message_nl, applies_to_module, active. Backend evalueert: IF ingredient IN product AND dose operator threshold THEN set flag.
A4: rule_id | B4: ingredient_name | C4: operator | D4: threshold_value | E4: threshold_unit | F4: flag | G4: flag_category | H4: severity | I4: intake_match_field | J4: consumer_message_nl | K4: applies_to_module | L4: active
A5: ▸ 1 — NEUROTOXICITEIT
A6: CF001 | B6: Pyridoxine HCl; P-5-P; Vitamine B6 | C6: >= | D6: 25 | E6: mg/dag | F6: b6_risk | G6: Neurotoxiciteit | H6: Critical | I6: intake_meds_neurological; intake_supplements_b6 | J6: Dit product bevat een hoge B6-dosering. Langdurige inname boven 25 mg/dag kan bij sommige mensen perifere neuropathie veroorzaken. Gebruik niet structureel zonder begeleiding. | K6: VITAMIN; ALL | L6: Y
A7: CF002 | B7: Pyridoxine HCl; P-5-P; Vitamine B6 | C7: >= | D7: 50 | E7: mg/dag | F7: b6_high_dose | G7: Neurotoxiciteit | H7: Critical | I7: intake_meds_neurological; intake_supplements_b6 | J7: Dit product bevat een zeer hoge B6-dosering (≥50 mg/dag). Klinisch geassocieerd met sensorische neuropathie. Alleen bij specifieke therapeutische indicatie onder begeleiding. | K7: VITAMIN; ALL | L7: Y
A8: CF003 | B8: Retinol; Vitamine A (retinol); Retinoïden | C8: >= | D8: 3000 | E8: IU/dag | F8: high_dose_fat_soluble | G8: Neurotoxiciteit / Teratogeniciteit | H8: Critical | I8: intake_pregnancy; intake_liver_function | J8: Dit product bevat een hoge dosis vetoplosbare vitamine A (retinol). Accumulatie is mogelijk bij dagelijks gebruik. Niet aanbevolen tijdens zwangerschap. | K8: VITAMIN; ALL | L8: Y
A9: CF004 | B9: Retinol; Vitamine A (retinol) | C9: >= | D9: 10000 | E9: IU/dag | F9: pregnancy | G9: Teratogeniciteit | H9: Critical | I9: intake_pregnancy | J9: Hoge retinol-inname is geassocieerd met aangeboren afwijkingen. Dit product is niet geschikt tijdens zwangerschap. | K9: VITAMIN; ALL | L9: Y
A10: ▸ 2 — SCHILDKLIER
A11: CF005 | B11: Jodium; Kaliumjodide; Natriumjodide; Zeewier | C11: >= | D11: 150 | E11: mcg/dag | F11: thyroid_risk | G11: Schildklier | H11: Major | I11: intake_thyroid_condition; intake_meds_thyroid | J11: Dit product bevat jodium. Bij bestaande schildklierproblemen (Hashimoto, hyper- of hypothyreoïdie) kan extra jodium klachten verergeren. | K11: MINERAL; ALL | L11: Y
A12: CF006 | B12: Jodium; Kelp; Blaaswier; Fucus vesiculosus | C12: >= | D12: 500 | E12: mcg/dag | F12: iodine_risk | G12: Schildklier | H12: Critical | I12: intake_thyroid_condition; intake_meds_thyroid | J12: Zeer hoge jodium-inname. Boven 500 mcg/dag bestaat risico op jodium-geïnduceerde schildklierproblematiek, ook bij personen zonder voorgeschiedenis. | K12: MINERAL; BOTANICAL; ALL | L12: Y
A13: CF007 | B13: Ashwagandha; Withania somnifera | C13: any | D13: 0 | F13: thyroid_risk | G13: Schildklier | H13: Major | I13: intake_thyroid_condition; intake_meds_thyroid | J13: Ashwagandha kan de schildklierfunctie beïnvloeden. Bij bestaande schildklierproblematiek of medicatie: gebruik alleen onder begeleiding. | K13: BOTANICAL | L13: Y
A14: ▸ 3 — IJZER & MINERAALBALANS
A15: CF008 | B15: IJzer; Ferrum; FeSO4; Ferrousfumaraat; IJzerbisglycinaat | C15: any | D15: 0 | F15: iron_risk | G15: Mineraalbalans | H15: Major | I15: intake_iron_status; intake_gender; intake_meds_anticoag | J15: IJzersuppletie is alleen zinvol bij aangetoond tekort (ferritine laag). Overmatige ijzerinname is geassocieerd met oxidatieve stress. Niet aanbevolen zonder indicatie. | K15: MINERAL; ALL | L15: Y
A16: CF009 | B16: IJzer; Ferrum | C16: >= | D16: 45 | E16: mg/dag | F16: iron_high_dose | G16: Mineraalbalans | H16: Critical | I16: intake_iron_status; intake_pregnancy; intake_gender | J16: Hoge ijzerdosering. Boven 45 mg/dag (EFSA UL) verhoogd risico op gastro-intestinale bijwerkingen en ijzertoxiciteit. Alleen onder medische supervisie. | K16: MINERAL; ALL | L16: Y
A17: CF010 | B17: Zink; Zinkbisglycinaat; Zinkcitraat; Zinksulfaat | C17: >= | D17: 25 | E17: mg/dag | F17: zinc_copper_depletion | G17: Mineraalbalans | H17: Major | I17: intake_supplements_copper; intake_supplements_zinc | J17: Hoge zink-inname (≥25 mg/dag) kan koper verdringen. Langdurig gebruik zonder koper-suppletie kan leiden tot koperdepletie en bloedarmoede. | K17: MINERAL; ALL | L17: Y
A18: CF011 | B18: Zink; Zinkbisglycinaat | C18: >= | D18: 40 | E18: mg/dag | F18: ul_risk | G18: Mineraalbalans / UL | H18: Critical | I18: intake_supplements_zinc | J18: Zinkdosering nadert de EFSA veiligheidsgrens (40 mg/dag). Niet combineren met andere zinkbevattende supplementen of zinkrijke voeding. | K18: MINERAL; ALL | L18: Y
A19: CF012 | B19: Calcium; Calciumcarbonaat; Calciumcitraat | C19: >= | D19: 1200 | E19: mg/dag | F19: calcium_absorption_block | G19: Mineraalbalans | H19: Major | I19: intake_supplements_calcium; intake_supplements_iron; intake_supplements_zinc | J19: Hoge calcium-inname kan de opname van ijzer, zink en magnesium verminderen. Neem niet gelijktijdig in met andere mineralen. | K19: MINERAL; ALL | L19: Y
A20: CF013 | B20: Selenium; Natriumseleniet; Selenomethionine | C20: >= | D20: 200 | E20: mcg/dag | F20: selenium_risk | G20: Mineraalbalans / UL | H20: Major | I20: intake_supplements_selenium | J20: Selenium heeft een smal therapeutisch venster. Boven 200 mcg/dag nader aan de EFSA UL van 300 mcg. Chronische hoge inname geassocieerd met selenose. | K20: MINERAL; ALL | L20: Y
A21: ▸ 4 — BLOEDSTOLLING & MEDICATIE-INTERACTIES
A22: CF014 | B22: Vitamine K2; MK-7; Menaquinon; Vitamine K1; Phylloquinon | C22: any | D22: 0 | F22: anticoagulant | G22: Medicatie-interactie | H22: Critical | I22: intake_meds_anticoagulant; intake_meds_warfarin | J22: Vitamine K interfereert direct met Coumarines (Acenocoumarol, Warfarine). Bij gebruik van bloedverdunners: gebruik dit product NIET zonder overleg met arts. | K22: VITAMIN; ALL | L22: Y
A23: CF015 | B23: Omega-3 vetzuren; EPA; DHA; Visolie; Levertraan | C23: >= | D23: 3000 | E23: mg/dag | F23: anticoagulant | G23: Bloedstolling | H23: Major | I23: intake_meds_anticoagulant; intake_surgery_planned | J23: Hoge omega-3 dosering (≥3 g/dag) heeft mild bloedverdunnend effect. Bij gebruik van antistollingsmedicatie of geplande operatie: overleg met arts. | K23: OMEGA3; ALL | L23: Y
A24: CF016 | B24: Knoflookextract; Allium sativum; Ginkgo biloba; Ginkgo | C24: any | D24: 0 | F24: anticoagulant | G24: Bloedstolling | H24: Major | I24: intake_meds_anticoagulant | J24: Dit botanische ingrediënt heeft bloedverdunnende eigenschappen. Niet combineren met antistollingsmedicatie zonder medisch advies. | K24: BOTANICAL; ALL | L24: Y
A25: CF017 | B25: Sint-Janskruid; Hypericum perforatum | C25: any | D25: 0 | F25: drug_interaction_cyp3a4 | G25: Medicatie-interactie | H25: Critical | I25: intake_meds_any | J25: Sint-Janskruid is een sterke CYP3A4-inducer en verlaagt de werkzaamheid van veel medicijnen (anticonceptie, antidepressiva, bloedverdunners, HIV-medicatie). Niet combineren met medicijnen. | K25: BOTANICAL; ALL | L25: Y
A26: CF018 | B26: Curcumine; Curcuma longa; Kurkuma | C26: >= | D26: 500 | E26: mg/dag | F26: anticoagulant | G26: Bloedstolling / Medicatie | H26: Major | I26: intake_meds_anticoagulant; intake_gallbladder | J26: Hoge curcumine-dosering heeft anticoagulerend effect en kan de galblaasfunctie stimuleren. Bij galstenen of antistollingsmedicatie: gebruik voorzichtig. | K26: BOTANICAL; POLYPHENOL; ALL | L26: Y
A27: ▸ 5 — ZWANGERSCHAP & LACTATIE
A28: CF019 | B28: Retinol; Vitamine A | C28: >= | D28: 800 | E28: mcg/dag | F28: pregnancy | G28: Teratogeniciteit | H28: Critical | I28: intake_pregnancy; intake_lactation | J28: Vitamine A (retinol) boven aanbevolen zwangerschapsdosering. Hoog risico bij zwangerschap. | K28: VITAMIN; ALL | L28: Y
A29: CF020 | B29: Ashwagandha; Withania somnifera; Rhodiola; Rhodiola rosea | C29: any | D29: 0 | F29: pregnancy | G29: Zwangerschap / Adaptogenen | H29: Critical | I29: intake_pregnancy; intake_lactation | J29: Adaptogenen zijn onvoldoende onderzocht op veiligheid tijdens zwangerschap en borstvoeding. Gebruik wordt afgeraden. | K29: BOTANICAL; ALL | L29: Y
A30: CF021 | B30: Vitamine B6; Pyridoxine HCl | C30: >= | D30: 10 | E30: mg/dag | F30: pregnancy | G30: Zwangerschap | H30: Major | I30: intake_pregnancy | J30: B6 boven 10 mg/dag tijdens zwangerschap: afstemmen met arts. B6 is bij misselijkheid wel therapeutisch ingezet maar de dosering dient begeleid te worden. | K30: VITAMIN; ALL | L30: Y
A31: CF022 | B31: Foliumzuur; Folaat; 5-MTHF; Methylfolaat | C31: any | D31: 0 | F31: pregnancy_positive | G31: Zwangerschap / Positief | H31: Info | I31: intake_pregnancy; intake_pregnancy_planning | J31: Dit product bevat folaat — relevant bij zwangerschapswens en zwangerschap. Controleer of de dosering (minimaal 400 mcg/dag) voldoet aan de aanbevolen zwangerschapsdosering. | K31: VITAMIN; ALL | L31: Y
A32: CF023 | B32: Vitamine D3; Cholecalciferol | C32: >= | D32: 4000 | E32: IU/dag | F32: high_dose_fat_soluble | G32: Vetoplosbare vitaminen | H32: Major | I32: intake_pregnancy; intake_kidney_function | J32: Hoge vitamine D3 dosering. Bij zwangerschap of nierfunctiestoornissen: gebruik niet zonder medisch advies. Boven 4000 IU/dag nadert de EFSA veiligheidsgrens. | K32: VITAMIN; ALL | L32: Y
A33: ▸ 6 — NIER & LEVERFUNCTIE
A34: CF024 | B34: Vitamine C; Ascorbinezuur; Natriumascorbaat | C34: >= | D34: 1000 | E34: mg/dag | F34: kidney_risk | G34: Nierfunctie | H34: Major | I34: intake_kidney_function; intake_kidney_stones_history | J34: Hoge vitamine C dosering (≥1 g/dag) verhoogt de oxalaatexcretie via de nier. Bij nierstenen (calciumoxalaat) of verminderde nierfunctie: gebruik voorzichtig. | K34: VITAMIN; ALL | L34: Y
A35: CF025 | B35: Magnesium; Magnesiumbisglycinaat; Magnesiumoxide | C35: >= | D35: 350 | E35: mg/dag | F35: kidney_risk | G35: Nierfunctie | H35: Major | I35: intake_kidney_function | J35: Hoge magnesium-inname. Bij nierfunctiestoornissen kan magnesium niet adequaat uitgescheiden worden, wat leidt tot hypermagnesemie. | K35: MINERAL; ALL | L35: Y
A36: CF026 | B36: Creatine; Creatine monohydraat | C36: any | D36: 0 | F36: kidney_risk | G36: Nierfunctie | H36: Minor | I36: intake_kidney_function; intake_kidney_disease | J36: Creatinesuppletie verhoogt creatinine-waarden in het bloed, wat bloedtesten kan vertekenen. Bij verminderde nierfunctie: gebruik alleen na medisch overleg. | K36: AMINO; ALL | L36: Y
A37: CF027 | B37: Groene thee-extract; EGCG; Camellia sinensis | C37: >= | D37: 400 | E37: mg/dag | F37: liver_risk | G37: Leverfunctie | H37: Major | I37: intake_liver_function; intake_meds_hepatotoxic | J37: Geconcentreerde groene thee-extracten (≥400 mg EGCG/dag) zijn in zeldzame gevallen geassocieerd met leverschade (hepatotoxiciteit) bij nuchter gebruik. | K37: POLYPHENOL; BOTANICAL; ALL | L37: Y
A38: CF028 | B38: Niacine; Nicotinezuur; Vitamine B3 | C38: >= | D38: 500 | E38: mg/dag | F38: liver_risk | G38: Leverfunctie | H38: Major | I38: intake_liver_function; intake_diabetes | J38: Hoge niacine-dosering (≥500 mg/dag nicotinezuur) kan flush veroorzaken en bij langdurig gebruik lever-enzymstoringen geven. Nicotinamide heeft dit risico niet. | K38: VITAMIN; ALL | L38: Y
A39: ▸ 7 — SPORT & DOPING
A40: CF029 | B40: ANY | C40: sport_certified=N | D40: 0 | F40: sport_doping | G40: Sport / Doping | H40: Critical | I40: intake_sport_competitive; intake_sport_type | J40: Dit product heeft geen aantoonbare doping-certificering (bijv. Informed Sport, NZVT). Voor competitieve sporters bestaat risico op onbedoelde positieve dopingtest. | K40: SPORT; ALL | L40: Y
...

Sheet Engine_weight_explained
A1: Funcify — Engine Weight Verantwoording
A2: Per criterium: waarom heeft het dit gewicht en niet één punt hoger of lager? Waarom is het wel of niet kritisch? Dit document is de definitieve referentie voor alle discussies over de engine-weging.
A3: Categorie | B3: Criterium | C3: W | D3: Krit. | E3: Waarom dit gewicht | F3: Waarom niet hoger | G3: Waarom niet lager | H3: Waarom wel/niet kritisch
A4: Identity & Labeling
A5: Identity & Labeling | B5: Alle actieve ingrediënten + doseringen gedeclareerd, geen proprietary blend | C5: 8 | D5: Ja | E5: Zonder volledige declaratie is onafhankelijke beoordeling structureel onmogelijk. Proprietary blends zijn een bewuste keuze om transparantie te blokkeren en treffen de kernfunctie van de engine. | F5: Niet 10 omdat er nog geen bewijs van daadwerkelijke kwaliteitsproblemen is — het blokkeert beoordeling, maar bewijst geen slechte kwaliteit. Het COA-criterium (poort tot bewijs) staat hoger. | G5: Niet lager dan 8 omdat dit de absolutedrempel voor onafhankelijke analyse is. Elke beoordeling begint hier. | H5: Kritisch: zonder dit criterium is de engine niet bruikbaar. Een proprietary blend maakt alle kwaliteitsoordelen onmogelijk.
A6: Identity & Labeling | B6: Alle chemische vormen expliciet vermeld | C6: 8 | D6: Ja | E6: De moleculaire vorm bepaalt biobeschikbaarheid en effectiviteit direct. 'Magnesium' zonder vorm is functioneel geen informatie. Gelijke ernst als proprietary blend. | F6: Niet 10 omdat de beoordeling van de vorm zelf (inferieur of niet) in een apart criterium zit met ook weight 8. Dit criterium gaat over de aanwezigheid van de informatie, niet de kwaliteit. | G6: Niet lager omdat ontbrekende vorminformatie even schadelijk is als een proprietary blend: je weet niet wat je beoordeelt. | H6: Kritisch: zonder chemische vorminformatie kan moleculaire kwaliteit niet worden beoordeeld.
A7: Identity & Labeling | B7: Alle hulpstoffen volledig gedeclareerd | C7: 5 | D7: Ja | E7: Allergenen en ongewenste additieven (titaniumdioxide, talk, gelatine bij veganisten) zijn een reëel consumentrisico. Volledige declaratie is wettelijk verplicht en essentieel voor de excipient-beoordeling. | F7: Niet 8+ omdat hulpstoffen een aanvullende laag zijn bovenop de actieve ingrediënten. De consumentenimpact is reëel maar secundair aan de werkzame samenstelling. | G7: Niet lager dan 5 omdat een onjuiste of incomplete hulpstoffenlijst veiligheidsrisico's met zich meebrengt (allergenen). | H7: Kritisch: onvolledige hulpstoffdeclaratie kan actieve veiligheidsrisico's verbergen.
A8: Identity & Labeling | B8: Serving size, dagdosering en aantal servings eenduidig | C8: 5 | D8: Ja | E8: Zonder duidelijke serving-informatie is de dagelijkse inname niet te berekenen. Sommige fabrikanten vermelden doseringen per capsule maar niet het aantal capsules per dag om lage hoeveelheden te verhullen. | F8: Niet hoger dan 5 omdat dit een informatiecriterium is dat de gebruiker helpt maar geen directe kwaliteitsimplicatie heeft. | G8: Niet lager omdat onduidelijkheid hier leidt tot systematische onderbeoordeling of overbeoordeling van de dosering. | H8: Kritisch: zonder serving-informatie is dosering onbeoordeelbaar.
A9: Identity & Labeling | B9: Batch/lot en THT duidelijk vermeld | C9: 3 | D9: Ja | E9: Traceerbaarheid van batches is een basisvereiste voor productaansprakelijkheid en recall-geschiktheid. Essentieel voor de koppeling met COA. | F9: Niet hoger dan 3 omdat het ontbreken hiervan een administratieve tekortkoming is, niet per se een kwaliteitsprobleem van het product zelf. | G9: Niet lager dan 3 want zonder batch/lot is een COA niet batch-specifiek te verifiëren. | H9: Kritisch: zonder batch-informatie kan de COA niet worden gekoppeld aan het verkochte product.
A10: Identity & Labeling | B10: Contra-indicaties, allergenen en gebruiksaanwijzing helder | C10: 4 | D10: Ja | E10: Ontbrekende contra-indicaties en allergeneninformatie vormen een directe veiligheidsrisico, met name bij interacties met medicatie of voedselallergieën. | F10: Niet hoger dan 4 omdat dit informatieve veiligheidslaag is, niet de productformulering zelf. | G10: Niet lager want het betreft directe consumentveiligheid. | H10: Kritisch: ontbrekende veiligheidsinformatie kan direct letsel veroorzaken bij kwetsbare gebruikers.
A11: Identity & Labeling | B11: Opslag- en stabiliteitsinstructies passend | C11: 3 | D11: Nee | E11: Relevante informatie voor behoud van potentie bij de gebruiker. Niet kritisch omdat de impact afhankelijk is van gebruikersgedrag, niet van de productformulering. | F11: Niet hoger want onjuiste opslaginstructies beïnvloeden potentie maar vormen geen veiligheidsrisico. | G11: Niet lager dan 3 want ze zijn relevant voor productwerkzaamheid in de praktijk. | H11: Niet kritisch: een product met ontbrekende opslaginstructies kan nog steeds kwalitatief goed zijn.
A12: Identity & Labeling | B12: Producent of EU-verantwoordelijke volledig traceerbaar | C12: 6 | D12: Ja | E12: Een traceerbare verantwoordelijke partij is wettelijk verplicht in de EU en maakt aansprakelijkheid mogelijk. Zonder dit is de consument rechteloos bij kwaliteitsproblemen. | F12: Niet 8+ want de traceerbaarheid is een juridisch criterium, geen directe indicatie van productkwaliteit. | G12: Niet lager dan 6 want ontbreken hiervan is een ernstige compliance-overtreding. | H12: Kritisch: zonder verantwoordelijke partij bestaat er geen aanspreekpunt bij veiligheidsincidenten.
A13: Identity & Labeling | B13: COA per batch publiek en traceerbaar | C13: 10 | D13: Ja | E13: Het maximale gewicht is gerechtvaardigd omdat dit de absolute poort is naar enig extern bewijs van productkwaliteit. Zonder batch-specifieke COA is geen enkele kwaliteitsclaim verifieerbaar. De COA is de basis van de gehele bewijsketen. | F13: Niet te verlagen: dit is het hoogste punt in de bewijshiërarchie. Alle andere verificatiecriteria bouwen hierop voort. | G13: Niet lager dan 10 want er is geen criterium dat fundamenteler is voor externe verifieerbaarheid. | H13: Kritisch: zonder COA kan geen enkel kwaliteitsoordeel worden onderbouwd.
A14: Identity & Labeling | B14: COA extern geverifieerd via ISO 17025 | C14: 7 | D14: Ja | E14: Een rapport van een niet-geaccrediteerd lab heeft geen onafhankelijke bewijswaarde. Dit criterium beoordeelt de betrouwbaarheid van het bewijs dat via de COA (weight 10) is binnengekomen. De logische volgorde: eerst bewijs (10), dan kwaliteit van dat bewijs (7). | F14: Niet 10 want dit criterium staat hiërarchisch onder de aanwezigheid van de COA. Het is de kwaliteitslaag bovenop de poort, niet de poort zelf. | G14: Niet lager dan 7 want een COA van een niet-geaccrediteerd lab is gevaarlijker dan geen COA: het geeft een misleidende schijn van verificatie. | H14: Kritisch: een niet-geaccrediteerd lab maakt de gehele COA als bewijs onbruikbaar.
A15: Identity & Labeling | B15: Analysemethoden en LOQ/LOD passend | C15: 5 | D15: Nee | E15: De detectielimieten van de gebruikte analysemethode bepalen of verontreinigingen überhaupt gevonden kunnen worden. Een te hoge LOD mist relevante contaminatieniveaus. | F15: Niet hoger dan 5 want dit is een technische kwaliteitslaag van het testproces, niet direct een consumentenimpact. | G15: Niet lager dan 5 want inadequate methoden kunnen bewust of onbewust zorgen dat problemen onzichtbaar blijven. | H15: Niet kritisch: suboptimale methoden verminderen betrouwbaarheid maar zijn zelden een bewuste misleidingstactiek.
A16: Identity & Labeling | B16: Zware metalen en microbiologie getest | C16: 6 | D16: Ja | E16: Lood, cadmium, kwik en arseen zijn acuut en chronisch toxisch. Dit is een extern contaminatierisico afhankelijk van grondstoffen en productieomgeving. In de kernlaag weight 6 omdat het risico sterk producttype-afhankelijk is. In modules voor omega-3, botanicals en mineralen wordt dit verhoogd naar 8-10. | F16: Niet 8+ in de kernlaag omdat het risico bij sommige producttypes (bijv. vitamine D capsules) vrijwel nihil is. De modules compenseren dit voor risicocategorieën. | G16: Niet lager dan 6 want zware metalen zijn een absoluut veiligheidsprobleem wanneer ze boven de normen zitten. | H16: Kritisch: aantoonbare overschrijding van zware metalengrenzen is een directe gezondheidsbedreiging.
... A21: Identity & Labeling | B21: Eindgebruikersgroep vermeld indien relevant | C21: 5 | D21: Nee | E21: Supplementen voor specifieke doelgroepen (zwangeren, kinderen, senioren) vereisen aangepaste doseringen en waarschuwingen. Ontbreken hiervan is een informatierisico voor kwetsbare groepen. | F21: Niet hoger want dit is een context-informatiecriterium. De formulering zelf is al beoordeeld op veiligheid voor specifieke doelgroepen. | G21: Niet lager dan 5 want kwetsbare groepen kunnen ernstige schade ondervinden van onderdosering of overdosering. | H21: Niet kritisch: het ontbreken van doelgroepvermelding is een informatiegebrek; de veiligheidsrisico's worden via andere criteria gevangen.
A22: Core Quality – Raw Materials
A23: Core Quality – Raw Materials | B23: Hoofdingrediënt in klinisch inzetbare vorm | C23: 8 | D23: Ja | E23: De moleculaire vorm bepaalt of een ingrediënt het beoogde fysiologische effect kan bereiken. Een inferieure vorm maakt het product onwerkzaam ongeacht alle andere kwaliteitskenmerken. Dit raakt de kernbelofte van het supplement. | F23: Niet 10 want de COA (poort tot bewijs) staat hoger in de hiërarchie. Zonder COA is dit criterium niet te beoordelen. | G23: Niet lager dan 8 want een verkeerde moleculaire vorm is inhoudelijk gelijk aan een niet-werkend product. | H23: Kritisch: een inferieure hoofdvorm maakt de kernbelofte van het product onwaar.
A24: Core Quality – Raw Materials | B24: Vermijdt inferieure vormen (oxide, carbonate, foliumzuur, cyanocobalamine) | C24: 8 | D24: Ja | E24: MgO biobeschikbaarheid <5% vs bisglycinaat ~40%. Synthetisch foliumzuur onconverteerbaar bij MTHFR. Cyanocobalamine vereist detoxificatiestap. Dit zijn aantoonbare kwaliteitsproblemen met directe klinische consequenties. | F24: Niet 10 want dit criterium valideert de keuze van de vormhiërarchie — het hoofdvorm-criterium (ook 8) beoordeelt de aanwezigheid van een klinisch inzetbare vorm, dit criterium beoordeelt het vermijden van de slechte keuze. Samen gewicht 8+8. | G24: Niet lager dan 8 want inferieure vormen zijn een structureel kwaliteitsprobleem dat de werkzaamheid ondermijnt. | H24: Kritisch: een product dat bewust inferieure vormen toepast ondermijnt zijn eigen werkzaamheid.
A25: Core Quality – Raw Materials | B25: Identiteit actieve grondstof analytisch geverifieerd | C25: 6 | D25: Ja | E25: HPLC/FTIR of equivalente analyses bevestigen dat het geclaimde ingrediënt ook daadwerkelijk aanwezig is. Relevant bij dure of zeldzame actieve stoffen (ashwagandha-extract, probiotica strains). | F25: Niet 8+ want bij eenvoudige ingrediënten is identiteitsverificatie vrijwel standaard en de fraudeprevalentie is lager dan bij botanicals. | G25: Niet lager dan 6 want onbevestigde identiteit maakt het product onbeoordeelbaar op werkzaamheid. | H25: Kritisch: een niet-geverifieerde identiteit maakt alle kwaliteitsaanspraken onverifieerbaar.
A26: Core Quality – Raw Materials | B26: Geen verboden excipients (titaniumdioxide, talk) | C26: 4 | D26: Ja | E26: Titaniumdioxide is als voedingsadditief verboden in de EU. Talk en vergelijkbare excipients zijn in hoge concentraties problematisch. Dit betreft verboden stoffen, niet slechte keuzes. | F26: Niet 8+ want de prevalentie van bewuste overtreding is laag en de directe gezondheidsimpact in gangbare doseringen is beperkt. | G26: Niet lager dan 4 want het betreft wettelijk verboden additieven. | H26: Kritisch: het gebruik van EU-verboden additieven is een absolute regelovertreding.
A27: Core Quality – Raw Materials | B27: Botanische extracten correct gestandaardiseerd | C27: 4 | D27: Nee | E27: Standaardisatie op een markercompound garandeert dat de actieve fractie consistent aanwezig is. Relevant uitsluitend voor botanische ingrediënten. | F27: Niet hoger want dit is een categorie-specifiek criterium met beperkte universele toepassing. | G27: Niet lager dan 4 want zonder standaardisatie is een botanisch extract niet doseerbaar op werkzaamheid. | H27: Niet kritisch: ontbrekende standaardisatie vermindert kwaliteitszekerheid maar is niet per definitie een veiligheidsprobleem.
A28: Core Quality – Raw Materials | B28: Ingrediënten voldoen aan farmacopee-kwaliteit | C28: 4 | D28: Nee | E28: Farmacopee-normen (Ph.Eur., USP) geven zekerheid over zuiverheid en kwaliteitsparameters. Niet altijd verifieerbaar maar relevant als standaardbenchmark. | F28: Niet hoger want farmacopee-compliance is moeilijk te verifiëren zonder directe toeleveranciersdocumentatie. | G28: Niet lager dan 4 want het is een erkende kwaliteitsstandaard. | H28: Niet kritisch: veel kwalitatieve producten voldoen aan farmacopee-normen zonder dit expliciet te claimen.
A29: Core Quality – Metabolic Burden
A30: Core Quality – Metabolic Burden | B30: Langdurige inname zonder cumulatie- of toxiciteitsrisico | C30: 8 | D30: Ja | E30: Perifere neuropathie bij chronisch pyridoxine >25 mg/dag is klinisch gedocumenteerd. Retinolaccumulatie bij vetoplosbare vitaminen. Jodium-geïnduceerde schildklierdisfunctie. Dit zijn reële risico's bij regulier gebruik van gangbare doseringen. | F30: Niet 10 want de directe gezondheidsimpact is dosisafhankelijk en treedt op bij langdurig gebruik, niet acuut. Weight 10 is gereserveerd voor acute verificatiedrempels. | G30: Niet lager dan 8 want chronische toxiciteitsrisico's bij normaal gebruik zijn een ernstige veiligheidskwestie. | H30: Kritisch: langdurige inname van toxische doseringen kan irreversibele schade veroorzaken.
A31: Core Quality – Metabolic Burden | B31: Vormkeuze vereist geen onnodige metabolische omzetting | C31: 4 | D31: Nee | E31: Foliumzuur naar 5-MTHF omzetting is bij MTHFR-polymorfisme verminderd. Cyanocobalamine vereist cyanide-detoxificatie. Relevant maar minder kritisch dan de aanwezigheid van inferieure vormen. | F31: Niet hoger want dit is een verfijningscriterium bovenop de vormkwaliteitsbeoordeling die al in Raw Materials zit. | G31: Niet lager dan 4 want metabolische omzettingsproblemen hebben reële klinische consequenties bij specifieke populaties. | H31: Niet kritisch: de impact is populatiespecifiek en niet universeel van toepassing.
A32: Core Quality – Metabolic Burden | B32: GI-belasting passend | C32: 5 | D32: Nee | E32: Magnesiumoxide veroorzaakt bij hoge doseringen laxerende werking wat therapietrouw ondermijnt. GI-intolerantie leidt direct tot non-compliance, wat het effect van het supplement nillificeert. | F32: Niet hoger dan 5 want GI-belasting is een praktisch comfortkritiek, geen directe veiligheidsoverweging. | G32: Niet lager dan 5 want non-compliance door GI-problemen maakt het supplement effectief nutteloos. | H32: Niet kritisch: GI-belasting is oncomfortabel maar niet gevaarlijk bij normale gebruik.
A33: Core Quality – Metabolic Burden | B33: Relevante interacties of contra-indicaties benoemd | C33: 5 | D33: Ja | E33: Interacties met medicatie (vitamine K met coumarines, sint-janskruid als CYP3A4-inducer) zijn een direct veiligheidsrisico. Het niet vermelden hiervan is een actieve informatieverzuiming. | F33: Niet hoger dan 5 want de interactievermelding is een informatieverplichting, niet een formuleringsbeslis. De context flag rules vangen de inhoudelijke interactiebeoordeling. | G33: Niet lager dan 5 want ontbrekende interactie-informatie kan directe medicatierisico's veroorzaken. | H33: Kritisch: een niet vermelde interactie met gangbare medicatie is een actieve misleiding met potentieel ernstige gevolgen.
A34: Core Quality – Dosage & Evidence
A35: Core Quality – Dosage & Evidence | B35: Doseringen binnen klinisch relevante range | C35: 8 | D35: Ja | E35: Label decoration — sub-therapeutische doseringen uitsluitend voor de ingrediëntenlijst — is een van de meest prevalente misleidingspraktijken. Als de dosering niet klinisch relevant is, is de werkzaamheidsclaim misleidend. Gelijk gewicht aan vormen-criteria want de consequentie is identiek: het product werkt niet. | F35: Niet 10 want het doseercriterium staat in de bewijsketen onder de COA-poort. Bovendien is klinische relevantie soms contextafhankelijk (doel, gebruiker). | G35: Niet lager dan 8 want een sub-therapeutische dosering maakt de kernbelofte van het product onwaar. | H35: Kritisch: een product met een niet-relevante dosering van het hoofdingrediënt claimt effectiviteit die het structureel niet kan leveren.
A36: Core Quality – Dosage & Evidence | B36: Geen marketing-overdosering zonder onderbouwing | C36: 5 | D36: Nee | E36: Overdosering van bepaalde vitaminen en mineralen zonder klinische onderbouwing suggereert dat meer beter is, wat niet altijd klopt en soms schadelijk is. Relevant maar minder ernstig dan underdosering. | F36: Niet hoger want overdosering in supplementen is zelden gevaarlijk bij water-oplosbare stoffen, en de impact is minder direct dan underdosering. | G36: Niet lager dan 5 want misleidende mega-doseringsmarketing beïnvloedt koopbeslissingen en consumentverwachtingen. | H36: Niet kritisch: overdosering is context-afhankelijk beoordelen; de UL-criteria vangen de absolute veiligheidsgrens.
A37: Core Quality – Dosage & Evidence | B37: Synergie en ratio's logisch geformuleerd | C37: 6 | D37: Nee | E37: Zink >25 mg/dag zonder koper veroorzaakt koperdepletie bij langdurig gebruik. D3 zonder K2 bij hoge doses kan calciummetabolisme beïnvloeden. Verhoogd van 4 naar 6 vanwege reële klinische consequenties. Niet kritisch omdat de impact afhankelijk is van de totale supplementenstack, niet uitsluitend van dit product. | F37: Niet 8 want het effect is stack-afhankelijk. Een hoog-zink product is problematisch als de gebruiker geen koper gebruikt, maar dat ligt niet uitsluitend bij dit product. | G37: Niet lager dan 6 want de klinische consequenties van mineral antagonisme zijn reëel en gedocumenteerd. | H37: Niet kritisch: het risico is stack-afhankelijk en niet inherent aan het product zelf.
A38: Core Quality – Dosage & Evidence | B38: EFSA UL-veiligheidsgrenzen gerespecteerd | C38: 4 | D38: Ja | E38: De EFSA UL-waarden zijn de wetenschappelijke veiligheidsgrens. Overschrijding zonder klinische context is een veiligheidsfout. Weight 4 en niet hoger omdat UL-overschrijdingen in gangbare consumentensupplementen zeldzaam zijn. | F38: Niet 8+ want de marktprevalentie van bewuste UL-overschrijdingen is laag en de impact is dosisafhankelijk. De Metabolic Burden criteria vangen de specifieke toxiciteitsrisico's. | G38: Niet lager dan 4 want elke bewuste UL-overschrijding is per definitie een veiligheidsfout. | H38: Kritisch: een product dat de EFSA-veiligheidsgrens overschrijdt claimt veiligheid die het structureel niet heeft.
A39: Core Quality – Dosage & Evidence | B39: Evidence-niveau passend bij claim | C39: 3 | D39: Nee | E39: Een claim ondersteund door enkel in-vitro studies is zwakker dan een claim gebaseerd op humane RCT's. Informatief voor professionals maar beperkte directe consumentenimpact. | F39: Niet hoger want evidence-niveau is contextafhankelijk en de regulering van gezondheidsclaims wordt al via het claims-criterium gevangen. | G39: Niet lager dan 3 want het is relevante contextuele informatie voor de consument. | H39: Niet kritisch: een lager evidence-niveau is een kwaliteitsbeperking, geen misleiding als de claim conform EU-wetgeving is.
A40: Core Quality – Dosage & Evidence | B40: Bioavailability claims alleen bij humane data | C40: 4 | D40: Ja | E40: 'Liposomaal' en vergelijkbare biobeschikbaarheidsclaims zijn momenteel de meest misbruikte marketingterm in de sector. Zonder humane data is de claim misleidend. Dit criterium overlapt bewust met het technologieclaims-criterium in Delivery. | F40: Niet 6+ want dit criterium focust op de onderbouwing van de claim, het Delivery-criterium (6) beoordeelt of de technologie functioneel is. | G40: Niet lager dan 4 want een ongefundeerde biobeschikbaarheidsclaim beïnvloedt direct de aankoopbeslissing. | H40: Kritisch: een misleidende biobeschikbaarheidsclaim is de kern van de productpositionering bij deze producten.
A41: Core Quality – Dosage & Evidence | B41: Interactie-matrix geborgd (antagonisme) | C41: 7 | D41: Ja | E41: Calcium en ijzer in hoge doseringen in één product verminderen elkaars opname significant. Zink en koper zijn elkaars antagonisten. Dit wordt niet gevangen door afzonderlijke doseringsbeoordelingen — het vereist een beoordeling van de totale formulering. | F41: Niet 8 want het effect is dosisafhankelijk en niet bij elk multi-ingrediënt product relevant. | G41: Niet lager dan 7 want een formulering die actief de opname van eigen ingrediënten vermindert is een fundamenteel kwaliteitsprobleem. | H41: Kritisch: antagonistische formuleringen verminderen de werkzaamheid van het product in zijn geheel.
A42: Core Quality – Dosage & Evidence | B42: Seizoensgebondenheid gecontextualiseerd | C42: 4 | D42: Nee | E42: Vitamine D 1000 IU is in de Nederlandse winter ondergekwalificeerd; hetzelfde product is in de zomer met voldoende buitenactiviteit mogelijk overbodig. Relevant voor de personalisatie-engine maar beperkte directe productkwaliteitsimplicatie. | F42: Niet hoger want dit is een contextuele relevantie-factor, geen kwaliteitsgebrek van het product zelf. | G42: Niet lager dan 4 want seizoensgebonden onjuiste aanbevelingen kunnen leiden tot structurele tekorten of overinname. | H42: Niet kritisch: een product kan kwalitatief goed zijn maar seizoenscontextueel onoptimaal.
A43: Core Quality – Contaminants
